Traceback (most recent call last):
  File "d:/python3/py_test/mypro_exception/traceback_test.py", line 8, in <module>
    num = 1/0
ZeroDivisionError: division by zero
